<?xml version="1.0" ?>
<sdf version="1.10">
  <world name="mobile_base_minimal">
    <physics name="1ms" type="ignored">
      <max_step_size>0.001</max_step_size>
      <real_time_factor>1.0</real_time_factor>
    </physics>

    <plugin filename="gz-sim-physics-system" name="gz::sim::systems::Physics"/>
    <plugin filename="gz-sim-user-commands-system" name="gz::sim::systems::UserCommands"/>
    <plugin filename="gz-sim-scene-broadcaster-system" name="gz::sim::systems::SceneBroadcaster"/>

    <light name="sun" type="directional">
      <cast_shadows>true</cast_shadows>
      <pose>0 0 10 0 0 0</pose>
      <diffuse>0.8 0.8 0.8 1</diffuse>
      <specular>0.2 0.2 0.2 1</specular>
      <direction>-0.5 0.1 -0.9</direction>
    </light>

    <model name="ground_plane">
      <static>true</static>
      <link name="link">
        <collision name="collision">
          <geometry>
            <plane>
              <normal>0 0 1</normal>
              <size>10 10</size>
            </plane>
          </geometry>
        </collision>
        <visual name="visual">
          <geometry>
            <plane>
              <normal>0 0 1</normal>
              <size>10 10</size>
            </plane>
          </geometry>
          <material>
            <ambient>0.8 0.8 0.8 1</ambient>
            <diffuse>0.8 0.8 0.8 1</diffuse>
          </material>
        </visual>
      </link>
    </model>

    <model name="two_wheel_learning_base">
      <pose>0 0 0.18 0 0 0</pose>
      <link name="chassis">
        <inertial>
          <mass>5.0</mass>
          <inertia>
            <ixx>0.12</ixx>
            <iyy>0.12</iyy>
            <izz>0.12</izz>
          </inertia>
        </inertial>
        <collision name="collision">
          <geometry>
            <box>
              <size>0.6 0.4 0.2</size>
            </box>
          </geometry>
        </collision>
        <visual name="visual">
          <geometry>
            <box>
              <size>0.6 0.4 0.2</size>
            </box>
          </geometry>
          <material>
            <ambient>0.1 0.3 0.8 1</ambient>
            <diffuse>0.1 0.3 0.8 1</diffuse>
          </material>
        </visual>
      </link>

      <link name="left_wheel">
        <pose>0 0.25 0 -1.5708 0 0</pose>
        <collision name="collision">
          <geometry>
            <cylinder>
              <radius>0.12</radius>
              <length>0.06</length>
            </cylinder>
          </geometry>
        </collision>
        <visual name="visual">
          <geometry>
            <cylinder>
              <radius>0.12</radius>
              <length>0.06</length>
            </cylinder>
          </geometry>
          <material>
            <ambient>0.02 0.02 0.02 1</ambient>
            <diffuse>0.02 0.02 0.02 1</diffuse>
          </material>
        </visual>
      </link>

      <link name="right_wheel">
        <pose>0 -0.25 0 -1.5708 0 0</pose>
        <collision name="collision">
          <geometry>
            <cylinder>
              <radius>0.12</radius>
              <length>0.06</length>
            </cylinder>
          </geometry>
        </collision>
        <visual name="visual">
          <geometry>
            <cylinder>
              <radius>0.12</radius>
              <length>0.06</length>
            </cylinder>
          </geometry>
          <material>
            <ambient>0.02 0.02 0.02 1</ambient>
            <diffuse>0.02 0.02 0.02 1</diffuse>
          </material>
        </visual>
      </link>

      <joint name="left_wheel_joint" type="revolute">
        <parent>chassis</parent>
        <child>left_wheel</child>
        <axis>
          <xyz>0 1 0</xyz>
        </axis>
      </joint>

      <joint name="right_wheel_joint" type="revolute">
        <parent>chassis</parent>
        <child>right_wheel</child>
        <axis>
          <xyz>0 1 0</xyz>
        </axis>
      </joint>
    </model>
  </world>
</sdf>
